[ Error  ] 17:59:03 - [from: add_bot       ] - Errore: '569510835:AAGfajJMZ52Q9oVSxOqc3CtpjpRoYV43bgo' line: ~91
[ Error  ] 20:59:10 - [from: get_main_bot_token] - Errore: Errore critico, imposta la token del bot principale in Files/jsons/config.json line: ~25
[CRITICAL] 21:01:22 - [from: get_main_bot_token] - Errore critico: imposta la token del bot principale in Files/jsons/config.json line: ~25
[ Error  ] 21:16:19 - [from: update_handler] - Errore: Ho trovato un errore: riga 52 KeyError 'new_chat_members' line: ~73
[ Error  ] 12:42:08 - [from: update_handler] - Errore: Errore nell'update: {'update_id': 759323497, 'message': {'message_id': 65, 'from': {'id': 535017415, 'is_bot': False, 'first_name': 'hypocrisy', 'username': 'kfrahh', 'language_code': 'it-IT'}, 'chat': {'id': 535017415, 'first_name': 'hypocrisy', 'username': 'kfrahh', 'type': 'private'}, 'date': 1533465728, 'text': '/newbot', 'entities': [{'offset': 0, 'length': 7, 'type': 'bot_command'}]}} line: ~41
[ Error  ] 12:45:55 - [from: update_handler] - Errore: Ho trovato un errore: riga 43 AttributeError 'Infos' object has no attribute 'user' line: ~69
[ Error  ] 13:24:42 - [from: bot_init      ] - Errore: HTTPSConnectionPool(host='api.telegram.org', port=443): Max retries exceeded with url: /bot668408714:AAF0zTM_ewH74BwxcB-QpfEccIzE7tgPlcs/getMe (Caused by NewConnectionError('<urllib3.connection.VerifiedHTTPSConnection object at 0x03DC6930>: Failed to establish a new connection: [Errno 11001] getaddrinfo failed')) line: ~93
[ Error  ] 13:25:42 - [from: update_handler] - Errore: Ho trovato un errore: riga 43 AttributeError 'Infos' object has no attribute 'user' line: ~69
[ Error  ] 13:44:21 - [from: update_handler] - Errore: Ho trovato un errore: riga 43 AttributeError 'Infos' object has no attribute 'user' line: ~69
[ Error  ] 13:48:03 - [from: send          ] - Errore: Ho trovato un errore: riga 227 ConnectionError HTTPSConnectionPool(host='api.telegram.org', port=443): Max retries exceeded with url: /bot600169672:AAHMbrihDtylSGPi9abrs3yyOwz_pvotMto/sendChatAction?chat_id=439144659&action=typing (Caused by NewConnectionError("<urllib3.connection.VerifiedHTTPSConnection object at 0x03AA7850>: Failed to establish a new connection: [WinError 10060] Impossibile stabilire la connessione. Risposta non corretta della parte connessa dopo l'intervallo di tempo oppure mancata risposta dall'host collegato")) line: ~277
[ Error  ] 14:14:22 - [from: replacer      ] - Errore: Errore: argument of type 'NoneType' is not iterable line: ~292
[ Error  ] 14:34:37 - [from: bot_init      ] - Errore: HTTPSConnectionPool(host='api.telegram.org', port=443): Max retries exceeded with url: /bot668408714:AAF0zTM_ewH74BwxcB-QpfEccIzE7tgPlcs/getMe (Caused by NewConnectionError('<urllib3.connection.VerifiedHTTPSConnection object at 0x0362DB70>: Failed to establish a new connection: [Errno 11001] getaddrinfo failed')) line: ~93
[ Error  ] 14:34:37 - [from: bot_init      ] - Errore: HTTPSConnectionPool(host='api.telegram.org', port=443): Max retries exceeded with url: /bot600169672:AAHMbrihDtylSGPi9abrs3yyOwz_pvotMto/getMe (Caused by NewConnectionError('<urllib3.connection.VerifiedHTTPSConnection object at 0x0388E3F0>: Failed to establish a new connection: [Errno 11001] getaddrinfo failed')) line: ~93
[ Error  ] 14:34:37 - [from: bot_init      ] - Errore: HTTPSConnectionPool(host='api.telegram.org', port=443): Max retries exceeded with url: /bot597857131:AAHSGIcmBw2R50yjSlUWWKOU7KTi90aw4SU/getMe (Caused by NewConnectionError('<urllib3.connection.VerifiedHTTPSConnection object at 0x0388E370>: Failed to establish a new connection: [Errno 11001] getaddrinfo failed')) line: ~93
[ Error  ] 14:34:39 - [from: bot_init      ] - Errore: HTTPSConnectionPool(host='api.telegram.org', port=443): Max retries exceeded with url: /bot668408714:AAF0zTM_ewH74BwxcB-QpfEccIzE7tgPlcs/getMe (Caused by NewConnectionError('<urllib3.connection.VerifiedHTTPSConnection object at 0x03B6A470>: Failed to establish a new connection: [Errno 11001] getaddrinfo failed')) line: ~93
[ Error  ] 14:34:39 - [from: bot_init      ] - Errore: HTTPSConnectionPool(host='api.telegram.org', port=443): Max retries exceeded with url: /bot597857131:AAHSGIcmBw2R50yjSlUWWKOU7KTi90aw4SU/getMe (Caused by NewConnectionError('<urllib3.connection.VerifiedHTTPSConnection object at 0x03B6A3B0>: Failed to establish a new connection: [Errno 11001] getaddrinfo failed')) line: ~93
[ Error  ] 14:34:39 - [from: bot_init      ] - Errore: HTTPSConnectionPool(host='api.telegram.org', port=443): Max retries exceeded with url: /bot600169672:AAHMbrihDtylSGPi9abrs3yyOwz_pvotMto/getMe (Caused by NewConnectionError('<urllib3.connection.VerifiedHTTPSConnection object at 0x03B6A4F0>: Failed to establish a new connection: [Errno 11001] getaddrinfo failed')) line: ~93
[ Error  ] 14:34:47 - [from: bot_init      ] - Errore: HTTPSConnectionPool(host='api.telegram.org', port=443): Max retries exceeded with url: /bot597857131:AAHSGIcmBw2R50yjSlUWWKOU7KTi90aw4SU/getMe (Caused by NewConnectionError('<urllib3.connection.VerifiedHTTPSConnection object at 0x048C9D50>: Failed to establish a new connection: [Errno 11001] getaddrinfo failed')) line: ~93
[ Error  ] 14:34:47 - [from: bot_init      ] - Errore: HTTPSConnectionPool(host='api.telegram.org', port=443): Max retries exceeded with url: /bot668408714:AAF0zTM_ewH74BwxcB-QpfEccIzE7tgPlcs/getMe (Caused by NewConnectionError('<urllib3.connection.VerifiedHTTPSConnection object at 0x048C9E10>: Failed to establish a new connection: [Errno 11001] getaddrinfo failed')) line: ~93
[ Error  ] 14:34:47 - [from: bot_init      ] - Errore: HTTPSConnectionPool(host='api.telegram.org', port=443): Max retries exceeded with url: /bot600169672:AAHMbrihDtylSGPi9abrs3yyOwz_pvotMto/getMe (Caused by NewConnectionError('<urllib3.connection.VerifiedHTTPSConnection object at 0x048C9E90>: Failed to establish a new connection: [Errno 11001] getaddrinfo failed')) line: ~93
[ Error  ] 14:39:45 - [from: update_handler] - Errore: Ho trovato un errore: riga 43 AttributeError 'Infos' object has no attribute 'user' line: ~69
[ Error  ] 16:55:22 - [from: update_handler] - Errore: Ho trovato un errore: riga 43 AttributeError 'Infos' object has no attribute 'user' line: ~69
[ Error  ] 17:06:27 - [from: update_handler] - Errore: Errore nell'update: {'update_id': 485764249, 'message': {'message_id': 8, 'from': {'id': 535017415, 'is_bot': False, 'first_name': 'hypocrisy', 'username': 'kfrahh', 'language_code': 'it'}, 'chat': {'id': -1001185266033, 'title': 'ossy ho rifatto yuki', 'type': 'supergroup'}, 'date': 1533481588, 'left_chat_participant': {'id': 597857131, 'is_bot': True, 'first_name': 'Yuki', 'username': 'YukiFBot'}, 'left_chat_member': {'id': 597857131, 'is_bot': True, 'first_name': 'Yuki', 'username': 'YukiFBot'}}} line: ~41
[ Error  ] 19:09:52 - [from: update_handler] - Errore: Ho trovato un errore: riga 43 AttributeError 'Infos' object has no attribute 'user' line: ~69
[ Error  ] 20:07:35 - [from: backup        ] - Errore: [Errno 22] Invalid argument: 'Files/bot_files/597857131/backup - Sunday - 20:07:35.kb' line: ~728
[ Error  ] 20:08:17 - [from: backup        ] - Errore: [Errno 22] Invalid argument: 'Files/bot_files/597857131/backup - Sunday - 20:08:16.kb' line: ~728
[ Error  ] 21:00:14 - [from: update_handler] - Errore: Ho trovato un errore: riga 43 AttributeError 'Infos' object has no attribute 'user' line: ~69
[ Error  ] 21:00:14 - [from: update_handler] - Errore: Ho trovato un errore: riga 43 AttributeError 'Infos' object has no attribute 'user' line: ~69
[ Error  ] 23:29:52 - [from: command_reader] - Errore: Ho trovato un errore: riga 347 KeyError '-255555457' () line: ~363
[ Error  ] 01:30:57 - [from: reader        ] - Errore: 'charmap' codec can't encode characters in position 38-42: character maps to <undefined> line: ~322
[ Error  ] 13:47:00 - [from: bot_init      ] - Errore: HTTPSConnectionPool(host='api.telegram.org', port=443): Max retries exceeded with url: /bot600169672:AAHMbrihDtylSGPi9abrs3yyOwz_pvotMto/getMe (Caused by NewConnectionError('<urllib3.connection.VerifiedHTTPSConnection object at 0x037683F0>: Failed to establish a new connection: [Errno 11001] getaddrinfo failed')) line: ~93
[ Error  ] 13:47:00 - [from: bot_init      ] - Errore: HTTPSConnectionPool(host='api.telegram.org', port=443): Max retries exceeded with url: /bot648162879:AAGksVrkr5Mce-GroSNdwtE9Hku-OFLvgXs/getMe (Caused by NewConnectionError('<urllib3.connection.VerifiedHTTPSConnection object at 0x049AF290>: Failed to establish a new connection: [Errno 11001] getaddrinfo failed')) line: ~93
[ Error  ] 13:47:00 - [from: bot_init      ] - Errore: HTTPSConnectionPool(host='api.telegram.org', port=443): Max retries exceeded with url: /bot657660561:AAG9Ck_AFr_YC5FlQ_KwZwWntzoCsU5KGKQ/getMe (Caused by NewConnectionError('<urllib3.connection.VerifiedHTTPSConnection object at 0x049AF210>: Failed to establish a new connection: [Errno 11001] getaddrinfo failed')) line: ~93
[ Error  ] 13:54:09 - [from: bot_init      ] - Errore: Errore sconosciuto: Conflict: can't use getUpdates method while webhook is active line: ~93
[ Error  ] 14:03:39 - [from: bot_init      ] - Errore: Errore sconosciuto: Conflict: can't use getUpdates method while webhook is active line: ~93
[ Error  ] 14:05:45 - [from: bot_init      ] - Errore: Errore sconosciuto: Conflict: can't use getUpdates method while webhook is active line: ~93
[ Error  ] 14:08:36 - [from: bot_init      ] - Errore: Errore sconosciuto: Conflict: can't use getUpdates method while webhook is active line: ~93
[ Error  ] 14:09:48 - [from: bot_init      ] - Errore: HTTPSConnectionPool(host='api.telegram.org', port=443): Max retries exceeded with url: /bot657660561:AAG9Ck_AFr_YC5FlQ_KwZwWntzoCsU5KGKQ/getMe (Caused by NewConnectionError('<urllib3.connection.VerifiedHTTPSConnection object at 0x04AF3050>: Failed to establish a new connection: [Errno 11001] getaddrinfo failed')) line: ~93
[ Error  ] 14:09:48 - [from: bot_init      ] - Errore: HTTPSConnectionPool(host='api.telegram.org', port=443): Max retries exceeded with url: /bot597857131:AAHSGIcmBw2R50yjSlUWWKOU7KTi90aw4SU/getMe (Caused by NewConnectionError('<urllib3.connection.VerifiedHTTPSConnection object at 0x04AF3150>: Failed to establish a new connection: [Errno 11001] getaddrinfo failed')) line: ~93
[ Error  ] 14:09:48 - [from: bot_init      ] - Errore: HTTPSConnectionPool(host='api.telegram.org', port=443): Max retries exceeded with url: /bot668408714:AAF0zTM_ewH74BwxcB-QpfEccIzE7tgPlcs/getMe (Caused by NewConnectionError('<urllib3.connection.VerifiedHTTPSConnection object at 0x03FDFFB0>: Failed to establish a new connection: [Errno 11001] getaddrinfo failed')) line: ~93
[ Error  ] 14:09:48 - [from: bot_init      ] - Errore: HTTPSConnectionPool(host='api.telegram.org', port=443): Max retries exceeded with url: /bot600169672:AAHMbrihDtylSGPi9abrs3yyOwz_pvotMto/getMe (Caused by NewConnectionError('<urllib3.connection.VerifiedHTTPSConnection object at 0x04AF30D0>: Failed to establish a new connection: [Errno 11001] getaddrinfo failed')) line: ~93
[ Error  ] 14:09:48 - [from: bot_init      ] - Errore: HTTPSConnectionPool(host='api.telegram.org', port=443): Max retries exceeded with url: /bot635998744:AAG0P2Kx_L4CHYcchs5_fmLMMwSw06FuTL4/getMe (Caused by NewConnectionError('<urllib3.connection.VerifiedHTTPSConnection object at 0x03FDFEF0>: Failed to establish a new connection: [Errno 11001] getaddrinfo failed')) line: ~93
[ Error  ] 14:10:05 - [from: bot_init      ] - Errore: HTTPSConnectionPool(host='api.telegram.org', port=443): Max retries exceeded with url: /bot668408714:AAF0zTM_ewH74BwxcB-QpfEccIzE7tgPlcs/getMe (Caused by NewConnectionError('<urllib3.connection.VerifiedHTTPSConnection object at 0x03ACADB0>: Failed to establish a new connection: [Errno 11001] getaddrinfo failed')) line: ~93
[ Error  ] 14:10:48 - [from: bot_init      ] - Errore: Errore sconosciuto: Conflict: can't use getUpdates method while webhook is active line: ~93
[ Error  ] 14:12:24 - [from: get_prop_id   ] - Errore: Token non trovata nel db. line: ~101
[ Error  ] 14:12:24 - [from: get_prop_id   ] - Errore: Token non trovata nel db. line: ~101
[ Error  ] 17:22:04 - [from: update_handler] - Errore: Ho trovato un errore: riga 43 AttributeError 'Infos' object has no attribute 'user' line: ~69
[ Error  ] 21:00:52 - [from: update_handler] - Errore: Ho trovato un errore: riga 43 AttributeError 'Infos' object has no attribute 'user' line: ~69
[ Error  ] 21:36:11 - [from: update_handler] - Errore: Ho trovato un errore: riga 43 AttributeError 'Infos' object has no attribute 'user' line: ~69
[ Error  ] 21:43:27 - [from: update_handler] - Errore: Errore nell'update: {'update_id': 862249509, 'message': {'message_id': 10603, 'from': {'id': 525781791, 'is_bot': False, 'first_name': 'sofi', 'username': 'SoFiA121720'}, 'chat': {'id': -1001370485817, 'title': 'Gay', 'type': 'supergroup'}, 'date': 1533757407, 'text': '/'}} line: ~41
[ Error  ] 21:44:44 - [from: update_handler] - Errore: Errore nell'update: {'update_id': 862249529, 'message': {'message_id': 621, 'from': {'id': 525781791, 'is_bot': False, 'first_name': 'sofi', 'username': 'SoFiA121720', 'language_code': 'it'}, 'chat': {'id': 525781791, 'first_name': 'sofi', 'username': 'SoFiA121720', 'type': 'private'}, 'date': 1533757484, 'text': '/'}} line: ~41
[ Error  ] 22:20:31 - [from: update_handler] - Errore: Ho trovato un errore: riga 43 AttributeError 'Infos' object has no attribute 'user' line: ~69
[ Error  ] 14:18:28 - [from: bot_init      ] - Errore: HTTPSConnectionPool(host='api.telegram.org', port=443): Max retries exceeded with url: /bot668408714:AAF0zTM_ewH74BwxcB-QpfEccIzE7tgPlcs/getMe (Caused by NewConnectionError('<urllib3.connection.VerifiedHTTPSConnection object at 0x04DDC170>: Failed to establish a new connection: [Errno 11001] getaddrinfo failed')) line: ~93
[ Error  ] 14:18:28 - [from: bot_init      ] - Errore: HTTPSConnectionPool(host='api.telegram.org', port=443): Max retries exceeded with url: /bot600169672:AAHMbrihDtylSGPi9abrs3yyOwz_pvotMto/getMe (Caused by NewConnectionError('<urllib3.connection.VerifiedHTTPSConnection object at 0x04DDC430>: Failed to establish a new connection: [Errno 11001] getaddrinfo failed')) line: ~93
[ Error  ] 14:18:28 - [from: bot_init      ] - Errore: HTTPSConnectionPool(host='api.telegram.org', port=443): Max retries exceeded with url: /bot597857131:AAHSGIcmBw2R50yjSlUWWKOU7KTi90aw4SU/getMe (Caused by NewConnectionError('<urllib3.connection.VerifiedHTTPSConnection object at 0x04DDC530>: Failed to establish a new connection: [Errno 11001] getaddrinfo failed')) line: ~93
[ Error  ] 14:18:28 - [from: bot_init      ] - Errore: HTTPSConnectionPool(host='api.telegram.org', port=443): Max retries exceeded with url: /bot589696502:AAHCymehEgNI281wMUOl5rU_QdWeq89XgM8/getMe (Caused by NewConnectionError('<urllib3.connection.VerifiedHTTPSConnection object at 0x04DDCAB0>: Failed to establish a new connection: [Errno 11001] getaddrinfo failed')) line: ~93
[ Error  ] 14:18:28 - [from: bot_init      ] - Errore: HTTPSConnectionPool(host='api.telegram.org', port=443): Max retries exceeded with url: /bot657910772:AAF20IDhag8AeuSYBEMUxtMRo_CoehvOnxQ/getMe (Caused by NewConnectionError('<urllib3.connection.VerifiedHTTPSConnection object at 0x04DDCB30>: Failed to establish a new connection: [Errno 11001] getaddrinfo failed')) line: ~93
[ Error  ] 14:18:28 - [from: bot_init      ] - Errore: HTTPSConnectionPool(host='api.telegram.org', port=443): Max retries exceeded with url: /bot680545552:AAEpujrzwX8YBtAEDjvRbT_AwnR1Xbze_jA/getMe (Caused by NewConnectionError('<urllib3.connection.VerifiedHTTPSConnection object at 0x04DDCBB0>: Failed to establish a new connection: [Errno 11001] getaddrinfo failed')) line: ~93
[ Error  ] 14:18:28 - [from: bot_init      ] - Errore: HTTPSConnectionPool(host='api.telegram.org', port=443): Max retries exceeded with url: /bot657660561:AAG9Ck_AFr_YC5FlQ_KwZwWntzoCsU5KGKQ/getMe (Caused by NewConnectionError('<urllib3.connection.VerifiedHTTPSConnection object at 0x04DDC7F0>: Failed to establish a new connection: [Errno 11001] getaddrinfo failed')) line: ~93
[ Error  ] 18:42:01 - [from: reader        ] - Errore: 'charmap' codec can't encode character '\u2764' in position 16: character maps to <undefined> line: ~322
[ Error  ] 20:03:30 - [from: reader        ] - Errore: 'charmap' codec can't encode characters in position 17-19: character maps to <undefined> line: ~322
[ Error  ] 20:03:58 - [from: reader        ] - Errore: 'charmap' codec can't encode characters in position 9-11: character maps to <undefined> line: ~322
[ Error  ] 22:57:09 - [from: update_handler] - Errore: Ho trovato un errore: riga 43 AttributeError 'Infos' object has no attribute 'user' line: ~69
[ Error  ] 22:57:09 - [from: update_handler] - Errore: Ho trovato un errore: riga 43 AttributeError 'Infos' object has no attribute 'user' line: ~69
[ Error  ] 22:57:09 - [from: update_handler] - Errore: Ho trovato un errore: riga 43 AttributeError 'Infos' object has no attribute 'user' line: ~69
[ Error  ] 22:57:14 - [from: update_handler] - Errore: Ho trovato un errore: riga 43 AttributeError 'Infos' object has no attribute 'user' line: ~69
[ Error  ] 23:00:05 - [from: update_handler] - Errore: Ho trovato un errore: riga 43 AttributeError 'Infos' object has no attribute 'user' line: ~69
[ Error  ] 23:00:05 - [from: update_handler] - Errore: Ho trovato un errore: riga 43 AttributeError 'Infos' object has no attribute 'user' line: ~69
[ Error  ] 23:00:05 - [from: update_handler] - Errore: Ho trovato un errore: riga 43 AttributeError 'Infos' object has no attribute 'user' line: ~69
[ Error  ] 23:00:05 - [from: update_handler] - Errore: Ho trovato un errore: riga 43 AttributeError 'Infos' object has no attribute 'user' line: ~69
[ Error  ] 23:00:18 - [from: update_handler] - Errore: Ho trovato un errore: riga 43 AttributeError 'Infos' object has no attribute 'user' line: ~69
[ Error  ] 23:00:18 - [from: update_handler] - Errore: Ho trovato un errore: riga 43 AttributeError 'Infos' object has no attribute 'user' line: ~69
[ Error  ] 23:00:18 - [from: update_handler] - Errore: Ho trovato un errore: riga 43 AttributeError 'Infos' object has no attribute 'user' line: ~69
[ Error  ] 23:00:18 - [from: update_handler] - Errore: Ho trovato un errore: riga 43 AttributeError 'Infos' object has no attribute 'user' line: ~69
[ Error  ] 23:01:32 - [from: update_handler] - Errore: Ho trovato un errore: riga 43 AttributeError 'Infos' object has no attribute 'user' line: ~69
[ Error  ] 23:01:32 - [from: update_handler] - Errore: Ho trovato un errore: riga 43 AttributeError 'Infos' object has no attribute 'user' line: ~69
[ Error  ] 23:01:32 - [from: update_handler] - Errore: Ho trovato un errore: riga 43 AttributeError 'Infos' object has no attribute 'user' line: ~69
[ Error  ] 23:01:32 - [from: update_handler] - Errore: Ho trovato un errore: riga 43 AttributeError 'Infos' object has no attribute 'user' line: ~69
[ Error  ] 23:02:15 - [from: update_handler] - Errore: Ho trovato un errore: riga 43 AttributeError 'Infos' object has no attribute 'user' line: ~69
[ Error  ] 23:02:15 - [from: update_handler] - Errore: Ho trovato un errore: riga 43 AttributeError 'Infos' object has no attribute 'user' line: ~69
[ Error  ] 23:02:15 - [from: update_handler] - Errore: Ho trovato un errore: riga 43 AttributeError 'Infos' object has no attribute 'user' line: ~69
[ Error  ] 23:02:15 - [from: update_handler] - Errore: Ho trovato un errore: riga 43 AttributeError 'Infos' object has no attribute 'user' line: ~69
[ Error  ] 23:03:28 - [from: update_handler] - Errore: Ho trovato un errore: riga 43 AttributeError 'Infos' object has no attribute 'user' line: ~69
[ Error  ] 23:03:28 - [from: update_handler] - Errore: Ho trovato un errore: riga 43 AttributeError 'Infos' object has no attribute 'user' line: ~69
[ Error  ] 23:03:28 - [from: update_handler] - Errore: Ho trovato un errore: riga 43 AttributeError 'Infos' object has no attribute 'user' line: ~69
[ Error  ] 23:03:28 - [from: update_handler] - Errore: Ho trovato un errore: riga 43 AttributeError 'Infos' object has no attribute 'user' line: ~69
[ Error  ] 23:04:25 - [from: update_handler] - Errore: Ho trovato un errore: riga 43 AttributeError 'Infos' object has no attribute 'user' line: ~69
[ Error  ] 23:04:25 - [from: update_handler] - Errore: Ho trovato un errore: riga 43 AttributeError 'Infos' object has no attribute 'user' line: ~69
[ Error  ] 23:04:25 - [from: update_handler] - Errore: Ho trovato un errore: riga 43 AttributeError 'Infos' object has no attribute 'user' line: ~69
[ Error  ] 23:04:32 - [from: update_handler] - Errore: Ho trovato un errore: riga 43 AttributeError 'Infos' object has no attribute 'user' line: ~69
[ Error  ] 23:04:39 - [from: update_handler] - Errore: Ho trovato un errore: riga 43 AttributeError 'Infos' object has no attribute 'user' line: ~69
[ Error  ] 23:04:39 - [from: update_handler] - Errore: Ho trovato un errore: riga 43 AttributeError 'Infos' object has no attribute 'user' line: ~69
[ Error  ] 23:04:39 - [from: update_handler] - Errore: Ho trovato un errore: riga 43 AttributeError 'Infos' object has no attribute 'user' line: ~69
[ Error  ] 23:04:39 - [from: update_handler] - Errore: Ho trovato un errore: riga 43 AttributeError 'Infos' object has no attribute 'user' line: ~69
[ Error  ] 23:04:42 - [from: update_handler] - Errore: Ho trovato un errore: riga 43 AttributeError 'Infos' object has no attribute 'user' line: ~69
[ Error  ] 23:04:42 - [from: update_handler] - Errore: Ho trovato un errore: riga 43 AttributeError 'Infos' object has no attribute 'user' line: ~69
[ Error  ] 23:04:42 - [from: update_handler] - Errore: Ho trovato un errore: riga 43 AttributeError 'Infos' object has no attribute 'user' line: ~69
[ Error  ] 23:04:45 - [from: update_handler] - Errore: Ho trovato un errore: riga 43 AttributeError 'Infos' object has no attribute 'user' line: ~69
[ Error  ] 23:06:07 - [from: update_handler] - Errore: Ho trovato un errore: riga 43 AttributeError 'Infos' object has no attribute 'user' line: ~69
[ Error  ] 23:06:07 - [from: update_handler] - Errore: Ho trovato un errore: riga 43 AttributeError 'Infos' object has no attribute 'user' line: ~69
[ Error  ] 23:06:07 - [from: update_handler] - Errore: Ho trovato un errore: riga 43 AttributeError 'Infos' object has no attribute 'user' line: ~69
[ Error  ] 23:06:07 - [from: update_handler] - Errore: Ho trovato un errore: riga 43 AttributeError 'Infos' object has no attribute 'user' line: ~69
[ Error  ] 23:06:13 - [from: update_handler] - Errore: Ho trovato un errore: riga 43 AttributeError 'Infos' object has no attribute 'user' line: ~69
[ Error  ] 23:06:13 - [from: update_handler] - Errore: Ho trovato un errore: riga 43 AttributeError 'Infos' object has no attribute 'user' line: ~69
[ Error  ] 23:06:13 - [from: update_handler] - Errore: Ho trovato un errore: riga 43 AttributeError 'Infos' object has no attribute 'user' line: ~69
[ Error  ] 23:06:15 - [from: update_handler] - Errore: Ho trovato un errore: riga 43 AttributeError 'Infos' object has no attribute 'user' line: ~69
[ Error  ] 23:10:00 - [from: update_handler] - Errore: Ho trovato un errore: riga 43 AttributeError 'Infos' object has no attribute 'user' line: ~69
[ Error  ] 23:10:00 - [from: update_handler] - Errore: Ho trovato un errore: riga 43 AttributeError 'Infos' object has no attribute 'user' line: ~69
[ Error  ] 23:10:00 - [from: update_handler] - Errore: Ho trovato un errore: riga 43 AttributeError 'Infos' object has no attribute 'user' line: ~69
[ Error  ] 23:10:00 - [from: update_handler] - Errore: Ho trovato un errore: riga 43 AttributeError 'Infos' object has no attribute 'user' line: ~69
